[2025-08-14 12:22:47] [INFO    ] discord.client: logging in using static token
[2025-08-14 12:22:48] [INFO    ] discord.gateway: Shard ID None has connected to Gateway (Session ID: e69737957a919dae230cdab42203e86c).
Traceback (most recent call last):
  File "/home/brett_david_woodworth/SNL_Bot/bot.py", line 15, in <module>
    from sheets import get_tile_data, get_max_tile
  File "/home/brett_david_woodworth/SNL_Bot/sheets.py", line 13, in <module>
    creds = ServiceAccountCredentials.from_json_keyfile_name("creds.json", scope)
            ^^^^^^^^^^^^^^^^^^^^^^^^^^^^^^^^^^^^^^^^^^^^^^^^^^^^^^^^^^^^^^^^^^^^^
  File "/home/brett_david_woodworth/SNL_Bot/venv/lib/python3.11/site-packages/oauth2client/service_account.py", line 219, in from_json_keyfile_name
    with open(filename, 'r') as file_obj:
         ^^^^^^^^^^^^^^^^^^^
FileNotFoundError: [Errno 2] No such file or directory: 'creds.json'
[2025-08-14 12:35:24] [INFO    ] discord.client: logging in using static token
[2025-08-14 12:35:25] [INFO    ] discord.gateway: Shard ID None has connected to Gateway (Session ID: 52ee23eccbce88f328bffd5ed32ea3b0).
[2025-08-14 12:40:39] [ERROR   ] discord.app_commands.tree: Ignoring exception in command 'checkrolls'
Traceback (most recent call last):
  File "/home/brett_david_woodworth/SNL_Bot/venv/lib/python3.11/site-packages/discord/app_commands/commands.py", line 828, in _do_call
    return await self._callback(interaction, **params)  # type: ignore
           ^^^^^^^^^^^^^^^^^^^^^^^^^^^^^^^^^^^^^^^^^^^
  File "/home/brett_david_woodworth/SNL_Bot/bot.py", line 358, in checkrolls
    await interaction.response.send_message(
  File "/home/brett_david_woodworth/SNL_Bot/venv/lib/python3.11/site-packages/discord/interactions.py", line 801, in send_message
    await adapter.create_interaction_response(
  File "/home/brett_david_woodworth/SNL_Bot/venv/lib/python3.11/site-packages/discord/webhook/async_.py", line 219, in request
    raise NotFound(response, data)
discord.errors.NotFound: 404 Not Found (error code: 10062): Unknown interaction

The above exception was the direct cause of the following exception:

Traceback (most recent call last):
  File "/home/brett_david_woodworth/SNL_Bot/venv/lib/python3.11/site-packages/discord/app_commands/tree.py", line 1248, in _call
    await command._invoke_with_namespace(interaction, namespace)
  File "/home/brett_david_woodworth/SNL_Bot/venv/lib/python3.11/site-packages/discord/app_commands/commands.py", line 853, in _invoke_with_namespace
    return await self._do_call(interaction, transformed_values)
           ^^^^^^^^^^^^^^^^^^^^^^^^^^^^^^^^^^^^^^^^^^^^^^^^^^^^
  File "/home/brett_david_woodworth/SNL_Bot/venv/lib/python3.11/site-packages/discord/app_commands/commands.py", line 846, in _do_call
    raise CommandInvokeError(self, e) from e
discord.app_commands.errors.CommandInvokeError: Command 'checkrolls' raised an exception: NotFound: 404 Not Found (error code: 10062): Unknown interaction
[2025-08-14 12:40:43] [ERROR   ] discord.app_commands.tree: Ignoring exception in command 'checkrolls'
Traceback (most recent call last):
  File "/home/brett_david_woodworth/SNL_Bot/venv/lib/python3.11/site-packages/discord/app_commands/commands.py", line 828, in _do_call
    return await self._callback(interaction, **params)  # type: ignore
           ^^^^^^^^^^^^^^^^^^^^^^^^^^^^^^^^^^^^^^^^^^^
  File "/home/brett_david_woodworth/SNL_Bot/bot.py", line 384, in checkrolls
    await interaction.response.send_message(
  File "/home/brett_david_woodworth/SNL_Bot/venv/lib/python3.11/site-packages/discord/interactions.py", line 801, in send_message
    await adapter.create_interaction_response(
  File "/home/brett_david_woodworth/SNL_Bot/venv/lib/python3.11/site-packages/discord/webhook/async_.py", line 219, in request
    raise NotFound(response, data)
discord.errors.NotFound: 404 Not Found (error code: 10062): Unknown interaction

The above exception was the direct cause of the following exception:

Traceback (most recent call last):
  File "/home/brett_david_woodworth/SNL_Bot/venv/lib/python3.11/site-packages/discord/app_commands/tree.py", line 1248, in _call
    await command._invoke_with_namespace(interaction, namespace)
  File "/home/brett_david_woodworth/SNL_Bot/venv/lib/python3.11/site-packages/discord/app_commands/commands.py", line 853, in _invoke_with_namespace
    return await self._do_call(interaction, transformed_values)
           ^^^^^^^^^^^^^^^^^^^^^^^^^^^^^^^^^^^^^^^^^^^^^^^^^^^^
  File "/home/brett_david_woodworth/SNL_Bot/venv/lib/python3.11/site-packages/discord/app_commands/commands.py", line 846, in _do_call
    raise CommandInvokeError(self, e) from e
discord.app_commands.errors.CommandInvokeError: Command 'checkrolls' raised an exception: NotFound: 404 Not Found (error code: 10062): Unknown interaction
[2025-08-14 12:48:34] [ERROR   ] discord.app_commands.tree: Ignoring exception in command 'leaderboard'
Traceback (most recent call last):
  File "/home/brett_david_woodworth/SNL_Bot/venv/lib/python3.11/site-packages/discord/app_commands/commands.py", line 828, in _do_call
    return await self._callback(interaction, **params)  # type: ignore
           ^^^^^^^^^^^^^^^^^^^^^^^^^^^^^^^^^^^^^^^^^^^
  File "/home/brett_david_woodworth/SNL_Bot/bot.py", line 578, in leaderboard
    await interaction.response.defer()  # ✅ Minimal fix — prevents Unknown interaction error
    ^^^^^^^^^^^^^^^^^^^^^^^^^^^^^^^^^^
  File "/home/brett_david_woodworth/SNL_Bot/venv/lib/python3.11/site-packages/discord/interactions.py", line 661, in defer
    await adapter.create_interaction_response(
  File "/home/brett_david_woodworth/SNL_Bot/venv/lib/python3.11/site-packages/discord/webhook/async_.py", line 219, in request
    raise NotFound(response, data)
discord.errors.NotFound: 404 Not Found (error code: 10062): Unknown interaction

The above exception was the direct cause of the following exception:

Traceback (most recent call last):
  File "/home/brett_david_woodworth/SNL_Bot/venv/lib/python3.11/site-packages/discord/app_commands/tree.py", line 1248, in _call
    await command._invoke_with_namespace(interaction, namespace)
  File "/home/brett_david_woodworth/SNL_Bot/venv/lib/python3.11/site-packages/discord/app_commands/commands.py", line 853, in _invoke_with_namespace
    return await self._do_call(interaction, transformed_values)
           ^^^^^^^^^^^^^^^^^^^^^^^^^^^^^^^^^^^^^^^^^^^^^^^^^^^^
  File "/home/brett_david_woodworth/SNL_Bot/venv/lib/python3.11/site-packages/discord/app_commands/commands.py", line 846, in _do_call
    raise CommandInvokeError(self, e) from e
discord.app_commands.errors.CommandInvokeError: Command 'leaderboard' raised an exception: NotFound: 404 Not Found (error code: 10062): Unknown interaction
[2025-08-14 12:48:53] [ERROR   ] discord.app_commands.tree: Ignoring exception in command 'submit'
Traceback (most recent call last):
  File "/home/brett_david_woodworth/SNL_Bot/venv/lib/python3.11/site-packages/discord/app_commands/commands.py", line 828, in _do_call
    return await self._callback(interaction, **params)  # type: ignore
           ^^^^^^^^^^^^^^^^^^^^^^^^^^^^^^^^^^^^^^^^^^^
  File "/home/brett_david_woodworth/SNL_Bot/bot.py", line 403, in submit
    await interaction.response.defer(ephemeral=True)
  File "/home/brett_david_woodworth/SNL_Bot/venv/lib/python3.11/site-packages/discord/interactions.py", line 661, in defer
    await adapter.create_interaction_response(
  File "/home/brett_david_woodworth/SNL_Bot/venv/lib/python3.11/site-packages/discord/webhook/async_.py", line 219, in request
    raise NotFound(response, data)
discord.errors.NotFound: 404 Not Found (error code: 10062): Unknown interaction

The above exception was the direct cause of the following exception:

Traceback (most recent call last):
  File "/home/brett_david_woodworth/SNL_Bot/venv/lib/python3.11/site-packages/discord/app_commands/tree.py", line 1248, in _call
    await command._invoke_with_namespace(interaction, namespace)
  File "/home/brett_david_woodworth/SNL_Bot/venv/lib/python3.11/site-packages/discord/app_commands/commands.py", line 853, in _invoke_with_namespace
    return await self._do_call(interaction, transformed_values)
           ^^^^^^^^^^^^^^^^^^^^^^^^^^^^^^^^^^^^^^^^^^^^^^^^^^^^
  File "/home/brett_david_woodworth/SNL_Bot/venv/lib/python3.11/site-packages/discord/app_commands/commands.py", line 846, in _do_call
    raise CommandInvokeError(self, e) from e
discord.app_commands.errors.CommandInvokeError: Command 'submit' raised an exception: NotFound: 404 Not Found (error code: 10062): Unknown interaction
[2025-08-14 12:49:11] [ERROR   ] discord.app_commands.tree: Ignoring exception in command 'roll'
Traceback (most recent call last):
  File "/home/brett_david_woodworth/SNL_Bot/venv/lib/python3.11/site-packages/discord/app_commands/commands.py", line 828, in _do_call
    return await self._callback(interaction, **params)  # type: ignore
           ^^^^^^^^^^^^^^^^^^^^^^^^^^^^^^^^^^^^^^^^^^^
  File "/home/brett_david_woodworth/SNL_Bot/bot.py", line 189, in roll
    await interaction.response.defer(ephemeral=False)
  File "/home/brett_david_woodworth/SNL_Bot/venv/lib/python3.11/site-packages/discord/interactions.py", line 661, in defer
    await adapter.create_interaction_response(
  File "/home/brett_david_woodworth/SNL_Bot/venv/lib/python3.11/site-packages/discord/webhook/async_.py", line 219, in request
    raise NotFound(response, data)
discord.errors.NotFound: 404 Not Found (error code: 10062): Unknown interaction

The above exception was the direct cause of the following exception:

Traceback (most recent call last):
  File "/home/brett_david_woodworth/SNL_Bot/venv/lib/python3.11/site-packages/discord/app_commands/tree.py", line 1248, in _call
    await command._invoke_with_namespace(interaction, namespace)
  File "/home/brett_david_woodworth/SNL_Bot/venv/lib/python3.11/site-packages/discord/app_commands/commands.py", line 853, in _invoke_with_namespace
    return await self._do_call(interaction, transformed_values)
           ^^^^^^^^^^^^^^^^^^^^^^^^^^^^^^^^^^^^^^^^^^^^^^^^^^^^
  File "/home/brett_david_woodworth/SNL_Bot/venv/lib/python3.11/site-packages/discord/app_commands/commands.py", line 846, in _do_call
    raise CommandInvokeError(self, e) from e
discord.app_commands.errors.CommandInvokeError: Command 'roll' raised an exception: NotFound: 404 Not Found (error code: 10062): Unknown interaction
[2025-08-14 12:49:15] [ERROR   ] discord.app_commands.tree: Ignoring exception in command 'addroll'
Traceback (most recent call last):
  File "/home/brett_david_woodworth/SNL_Bot/venv/lib/python3.11/site-packages/discord/app_commands/commands.py", line 828, in _do_call
    return await self._callback(interaction, **params)  # type: ignore
           ^^^^^^^^^^^^^^^^^^^^^^^^^^^^^^^^^^^^^^^^^^^
  File "/home/brett_david_woodworth/SNL_Bot/bot.py", line 502, in addroll
    await interaction.response.send_message(f"{amount} roll(s) added to {user.mention}.")
  File "/home/brett_david_woodworth/SNL_Bot/venv/lib/python3.11/site-packages/discord/interactions.py", line 801, in send_message
    await adapter.create_interaction_response(
  File "/home/brett_david_woodworth/SNL_Bot/venv/lib/python3.11/site-packages/discord/webhook/async_.py", line 219, in request
    raise NotFound(response, data)
discord.errors.NotFound: 404 Not Found (error code: 10062): Unknown interaction

The above exception was the direct cause of the following exception:

Traceback (most recent call last):
  File "/home/brett_david_woodworth/SNL_Bot/venv/lib/python3.11/site-packages/discord/app_commands/tree.py", line 1248, in _call
    await command._invoke_with_namespace(interaction, namespace)
  File "/home/brett_david_woodworth/SNL_Bot/venv/lib/python3.11/site-packages/discord/app_commands/commands.py", line 853, in _invoke_with_namespace
    return await self._do_call(interaction, transformed_values)
           ^^^^^^^^^^^^^^^^^^^^^^^^^^^^^^^^^^^^^^^^^^^^^^^^^^^^
  File "/home/brett_david_woodworth/SNL_Bot/venv/lib/python3.11/site-packages/discord/app_commands/commands.py", line 846, in _do_call
    raise CommandInvokeError(self, e) from e
discord.app_commands.errors.CommandInvokeError: Command 'addroll' raised an exception: NotFound: 404 Not Found (error code: 10062): Unknown interaction
[2025-08-14 12:49:38] [ERROR   ] discord.app_commands.tree: Ignoring exception in command 'reset'
Traceback (most recent call last):
  File "/home/brett_david_woodworth/SNL_Bot/venv/lib/python3.11/site-packages/discord/app_commands/commands.py", line 828, in _do_call
    return await self._callback(interaction, **params)  # type: ignore
           ^^^^^^^^^^^^^^^^^^^^^^^^^^^^^^^^^^^^^^^^^^^
  File "/home/brett_david_woodworth/SNL_Bot/bot.py", line 714, in reset
    await interaction.response.send_message(
  File "/home/brett_david_woodworth/SNL_Bot/venv/lib/python3.11/site-packages/discord/interactions.py", line 801, in send_message
    await adapter.create_interaction_response(
  File "/home/brett_david_woodworth/SNL_Bot/venv/lib/python3.11/site-packages/discord/webhook/async_.py", line 219, in request
    raise NotFound(response, data)
discord.errors.NotFound: 404 Not Found (error code: 10062): Unknown interaction

The above exception was the direct cause of the following exception:

Traceback (most recent call last):
  File "/home/brett_david_woodworth/SNL_Bot/venv/lib/python3.11/site-packages/discord/app_commands/tree.py", line 1248, in _call
    await command._invoke_with_namespace(interaction, namespace)
  File "/home/brett_david_woodworth/SNL_Bot/venv/lib/python3.11/site-packages/discord/app_commands/commands.py", line 853, in _invoke_with_namespace
    return await self._do_call(interaction, transformed_values)
           ^^^^^^^^^^^^^^^^^^^^^^^^^^^^^^^^^^^^^^^^^^^^^^^^^^^^
  File "/home/brett_david_woodworth/SNL_Bot/venv/lib/python3.11/site-packages/discord/app_commands/commands.py", line 846, in _do_call
    raise CommandInvokeError(self, e) from e
discord.app_commands.errors.CommandInvokeError: Command 'reset' raised an exception: NotFound: 404 Not Found (error code: 10062): Unknown interaction
[2025-08-14 14:52:25] [INFO    ] discord.gateway: Shard ID None has successfully RESUMED session 52ee23eccbce88f328bffd5ed32ea3b0.
[2025-08-14 16:16:35] [INFO    ] discord.gateway: Shard ID None has successfully RESUMED session 52ee23eccbce88f328bffd5ed32ea3b0.
[2025-08-14 18:02:29] [INFO    ] discord.gateway: Shard ID None has successfully RESUMED session 52ee23eccbce88f328bffd5ed32ea3b0.
[2025-08-14 19:46:54] [ERROR   ] discord.app_commands.tree: Ignoring exception in command 'checkrolls'
Traceback (most recent call last):
  File "/home/brett_david_woodworth/SNL_Bot/venv/lib/python3.11/site-packages/discord/app_commands/commands.py", line 828, in _do_call
    return await self._callback(interaction, **params)  # type: ignore
           ^^^^^^^^^^^^^^^^^^^^^^^^^^^^^^^^^^^^^^^^^^^
  File "/home/brett_david_woodworth/SNL_Bot/bot.py", line 384, in checkrolls
    await interaction.response.send_message(
  File "/home/brett_david_woodworth/SNL_Bot/venv/lib/python3.11/site-packages/discord/interactions.py", line 801, in send_message
    await adapter.create_interaction_response(
  File "/home/brett_david_woodworth/SNL_Bot/venv/lib/python3.11/site-packages/discord/webhook/async_.py", line 219, in request
    raise NotFound(response, data)
discord.errors.NotFound: 404 Not Found (error code: 10062): Unknown interaction

The above exception was the direct cause of the following exception:

Traceback (most recent call last):
  File "/home/brett_david_woodworth/SNL_Bot/venv/lib/python3.11/site-packages/discord/app_commands/tree.py", line 1248, in _call
    await command._invoke_with_namespace(interaction, namespace)
  File "/home/brett_david_woodworth/SNL_Bot/venv/lib/python3.11/site-packages/discord/app_commands/commands.py", line 853, in _invoke_with_namespace
    return await self._do_call(interaction, transformed_values)
           ^^^^^^^^^^^^^^^^^^^^^^^^^^^^^^^^^^^^^^^^^^^^^^^^^^^^
  File "/home/brett_david_woodworth/SNL_Bot/venv/lib/python3.11/site-packages/discord/app_commands/commands.py", line 846, in _do_call
    raise CommandInvokeError(self, e) from e
discord.app_commands.errors.CommandInvokeError: Command 'checkrolls' raised an exception: NotFound: 404 Not Found (error code: 10062): Unknown interaction
[2025-08-14 20:50:53] [INFO    ] discord.gateway: Shard ID None has successfully RESUMED session 52ee23eccbce88f328bffd5ed32ea3b0.
[2025-08-14 23:34:58] [INFO    ] discord.gateway: Shard ID None has successfully RESUMED session 52ee23eccbce88f328bffd5ed32ea3b0.
[2025-08-15 01:31:05] [INFO    ] discord.gateway: Shard ID None has successfully RESUMED session 52ee23eccbce88f328bffd5ed32ea3b0.
[2025-08-15 04:39:41] [INFO    ] discord.gateway: Shard ID None has successfully RESUMED session 52ee23eccbce88f328bffd5ed32ea3b0.
[2025-08-15 06:15:41] [INFO    ] discord.gateway: Shard ID None has successfully RESUMED session 52ee23eccbce88f328bffd5ed32ea3b0.
[2025-08-15 06:55:11] [ERROR   ] discord.app_commands.tree: Ignoring exception in command 'checkrolls'
Traceback (most recent call last):
  File "/home/brett_david_woodworth/SNL_Bot/venv/lib/python3.11/site-packages/discord/app_commands/commands.py", line 828, in _do_call
    return await self._callback(interaction, **params)  # type: ignore
           ^^^^^^^^^^^^^^^^^^^^^^^^^^^^^^^^^^^^^^^^^^^
  File "/home/brett_david_woodworth/SNL_Bot/bot.py", line 384, in checkrolls
    await interaction.response.send_message(
  File "/home/brett_david_woodworth/SNL_Bot/venv/lib/python3.11/site-packages/discord/interactions.py", line 801, in send_message
    await adapter.create_interaction_response(
  File "/home/brett_david_woodworth/SNL_Bot/venv/lib/python3.11/site-packages/discord/webhook/async_.py", line 219, in request
    raise NotFound(response, data)
discord.errors.NotFound: 404 Not Found (error code: 10062): Unknown interaction

The above exception was the direct cause of the following exception:

Traceback (most recent call last):
  File "/home/brett_david_woodworth/SNL_Bot/venv/lib/python3.11/site-packages/discord/app_commands/tree.py", line 1248, in _call
    await command._invoke_with_namespace(interaction, namespace)
  File "/home/brett_david_woodworth/SNL_Bot/venv/lib/python3.11/site-packages/discord/app_commands/commands.py", line 853, in _invoke_with_namespace
    return await self._do_call(interaction, transformed_values)
           ^^^^^^^^^^^^^^^^^^^^^^^^^^^^^^^^^^^^^^^^^^^^^^^^^^^^
  File "/home/brett_david_woodworth/SNL_Bot/venv/lib/python3.11/site-packages/discord/app_commands/commands.py", line 846, in _do_call
    raise CommandInvokeError(self, e) from e
discord.app_commands.errors.CommandInvokeError: Command 'checkrolls' raised an exception: NotFound: 404 Not Found (error code: 10062): Unknown interaction
